<?xml version="1.0" ?>
<robot name="turtlebot3_waffle" xmlns:xacro="http://ros.org/wiki/xacro">

  <link name="base_footprint"/>

  <joint name="base_joint" type="fixed">
    <parent link="base_footprint"/>
    <child link="base_link" />
    <origin xyz="0 0 0.010" rpy="0 0 0"/>
  </joint>

  <link name="base_link">
    <visual>
      <origin xyz="0 0 0" rpy="0 0 3.14"/>
      <geometry>
        <mesh filename="package://aiformula_description/meshes/AIF_body.dae"/>
      </geometry>
    </visual>

    <collision>
      <origin xyz="0 0 0" rpy="0 0 3.14"/>
      <geometry>
        <mesh filename="package://aiformula_description/meshes/AIF_body.dae" />
      </geometry>
    </collision>

    <inertial>
      <origin xyz="0 0 0" rpy="0 0 3.14"/>
      <mass value="30"/>
      <inertia ixx="1.69600" ixy="0.000" ixz="0.000"
               iyy="2.00000" iyz="0.000"
               izz="2.89600" />
    </inertial>
  </link>

  <joint name="wheel_left_joint" type="continuous">
    <parent link="base_link"/>
    <child link="wheel_left_link"/>
    <origin xyz="0.0 0.3 0.0" rpy="1.57 0 1.57"/>
    <axis xyz="1 0 0"/>
  </joint>

  <link name="wheel_left_link">
    <visual>
      <origin xyz="0 0 0" rpy="0 0 0"/>
      <geometry>
        <mesh filename="package://aiformula_description/meshes/tire_v1.dae" scale="0.05 0.12 0.12"/>
      </geometry>
    </visual>

    <collision>
      <origin xyz="0 0 0" rpy="0 0 0"/>
      <geometry>
        <mesh filename="package://aiformula_description/meshes/tire_v1.dae" scale="0.05 0.12 0.12"/>
      </geometry>
    </collision>

    <inertial>
      <origin xyz="0 0 0" />
      <mass value="7.0" />
      <inertia ixx="0.04778" ixy="0.000" ixz="0.000"
               iyy="0.04778" iyz="0.000"
               izz="0.07875" />
      </inertial>
  </link>

  <joint name="wheel_right_joint" type="continuous">
    <parent link="base_link"/>
    <child link="wheel_right_link"/>
    <origin xyz="0.0 -0.3 0.0" rpy="1.57 0 1.57"/>
    <axis xyz="1 0 0"/>
  </joint>

  <link name="wheel_right_link">
    <visual>
      <origin xyz="0 0 0" rpy="0 0 0"/>
      <geometry>
        <mesh filename="package://aiformula_description/meshes/tire_v1.dae" scale="0.05 0.12 0.12"/>
      </geometry>
    </visual>

    <collision>
      <origin xyz="0 0 0" rpy="0 0 0"/>
      <geometry>
        <mesh filename="package://aiformula_description/meshes/tire_v1.dae" scale="0.05 0.12 0.12"/>
      </geometry>
    </collision>

    <inertial>
      <origin xyz="0 0 0" />
      <mass value="7.0" />
      <inertia ixx="0.04778" ixy="0.000" ixz="0.000"
               iyy="0.04778" iyz="0.000"
               izz="0.07875" />
      </inertial>
  </link>

  <joint name="caster_back_joint" type="fixed">
    <parent link="base_link"/>
    <child link="caster_back_link"/>
    <origin xyz="-0.85 0.0 0.0" rpy="1.57 0 1.57"/>
    <!-- <axis xyz="1 0 0"/> -->
  </joint>

  <link name="caster_back_link">
    <visual>
      <origin xyz="0 0 0" rpy="0 0 0"/>
      <geometry>
        <mesh filename="package://aiformula_description/meshes/tire_v1.dae" scale="0.1 0.1 0.1"/>
      </geometry>
    </visual>

   <collision>
      <origin xyz="0 0.001 0" rpy="0 0 0"/>
      <geometry>
        <box size="0.030 0.009 0.020"/>
      </geometry>
    </collision>

    <inertial>
      <origin xyz="0 0 0" />
      <mass value="0.005" />
      <inertia ixx="0.001" ixy="0.0" ixz="0.0"
               iyy="0.001" iyz="0.0"
               izz="0.001" />
    </inertial>
  </link>

  <!-- <joint name="caster_back_joint" type="continuous">
    <parent link="base_link"/>
    <child link="caster_back_link"/>
    <origin xyz="-0.85 0.0 0.0" rpy="0 0 1.57"/>
    <axis xyz="1 0 0"/>
  </joint>

  <link name="caster_back_link">
    <visual>
      <origin xyz="0 0 0" rpy="0 0 0"/>
      <geometry>
        <mesh filename="package://aiformula_description/meshes/tire_v1.dae" scale="0.1 0.1 0.1"/>
      </geometry>
    </visual>

    <collision>
      <origin xyz="0 0 0" rpy="0 0 0"/>
      <geometry>
        <mesh filename="package://aiformula_description/meshes/tire_v1.dae" scale="0.1 0.1 0.1"/>
      </geometry>
    </collision>

    <inertial>
      <origin xyz="0 0 0" />
      <mass value="5.0" />
      <inertia ixx="0.01517" ixy="0.0" ixz="0.0"
               iyy="0.01517" iyz="0.0"
               izz="0.02500" />
    </inertial>
  </link> -->

  <joint name="imu_joint" type="fixed">
    <parent link="base_link"/>
    <child link="imu_link"/>
    <origin xyz="0.0 0 0.068" rpy="0 0 0"/>
  </joint>

  <link name="imu_link"/>

  <joint name="camera_joint" type="fixed">
    <origin xyz="0.064 -0.065 0.44" rpy="0 0 0"/>
    <parent link="base_link"/>
    <child link="camera_link"/>
  </joint>

  <link name="camera_link">
    <visual>
     <origin xyz="0 0 0" rpy="1.57 0 1.57"/>
      <geometry>
       <mesh filename="package://aiformula_description/meshes/r200.dae" />
      </geometry>
    </visual>
    <collision>
      <origin xyz="0.003 0.065 0.007" rpy="0 0 0"/>
      <geometry>
        <box size="0.012 0.132 0.020"/>
      </geometry>
    </collision>

  </link>

  <joint name="camera_rgb_joint" type="fixed">
    <origin xyz="0.005 0.018 0.013" rpy="0 0 0"/>
    <parent link="camera_link"/>
    <child link="camera_rgb_frame"/>
  </joint>
  <link name="camera_rgb_frame"/>

  <joint name="camera_rgb_optical_joint" type="fixed">
    <origin xyz="0 0 0" rpy="-1.57 0 -1.57"/>
    <parent link="camera_rgb_frame"/>
    <child link="camera_rgb_optical_frame"/>
  </joint>
  <link name="camera_rgb_optical_frame"/>

  <joint name="camera_depth_joint" type="fixed">
    <origin xyz="0.005 0.028 0.013" rpy="0 0 0"/>
    <parent link="camera_link"/>
    <child link="camera_depth_frame"/>
  </joint>
  <link name="camera_depth_frame"/>

  <joint name="camera_depth_optical_joint" type="fixed">
    <origin xyz="0 0 0" rpy="-1.57 0 -1.57"/>
    <parent link="camera_depth_frame"/>
    <child link="camera_depth_optical_frame"/>
  </joint>
  <link name="camera_depth_optical_frame"/>

</robot>
